2025-08-16 19:58:27,628 ERROR: Exception on /api/auth/login [POST] [in /home/k4r4b0/Desktop/Projects/Python/Omnidesk/backend/venv/lib/python3.13/site-packages/flask/app.py:875]
Traceback (most recent call last):
  File "/home/k4r4b0/Desktop/Projects/Python/Omnidesk/backend/venv/lib/python3.13/site-packages/sqlalchemy/engine/base.py", line 1967, in _exec_single_context
    self.dialect.do_execute(
    ~~~~~~~~~~~~~~~~~~~~~~~^
        cursor, str_statement, effective_parameters, context
        ^^^^^^^^^^^^^^^^^^^^^^^^^^^^^^^^^^^^^^^^^^^^^^^^^^^^
    )
    ^
  File "/home/k4r4b0/Desktop/Projects/Python/Omnidesk/backend/venv/lib/python3.13/site-packages/sqlalchemy/engine/default.py", line 951, in do_execute
    cursor.execute(statement, parameters)
    ~~~~~~~~~~~~~~^^^^^^^^^^^^^^^^^^^^^^^
sqlite3.OperationalError: no such column: user.is_active

The above exception was the direct cause of the following exception:

Traceback (most recent call last):
  File "/home/k4r4b0/Desktop/Projects/Python/Omnidesk/backend/venv/lib/python3.13/site-packages/flask/app.py", line 1511, in wsgi_app
    response = self.full_dispatch_request()
  File "/home/k4r4b0/Desktop/Projects/Python/Omnidesk/backend/venv/lib/python3.13/site-packages/flask/app.py", line 919, in full_dispatch_request
    rv = self.handle_user_exception(e)
  File "/home/k4r4b0/Desktop/Projects/Python/Omnidesk/backend/venv/lib/python3.13/site-packages/flask_cors/extension.py", line 176, in wrapped_function
    return cors_after_request(app.make_response(f(*args, **kwargs)))
                                                ~^^^^^^^^^^^^^^^^^
  File "/home/k4r4b0/Desktop/Projects/Python/Omnidesk/backend/venv/lib/python3.13/site-packages/flask/app.py", line 917, in full_dispatch_request
    rv = self.dispatch_request()
  File "/home/k4r4b0/Desktop/Projects/Python/Omnidesk/backend/venv/lib/python3.13/site-packages/flask/app.py", line 902, in dispatch_request
    return self.ensure_sync(self.view_functions[rule.endpoint])(**view_args)  # type: ignore[no-any-return]
           ~~~~~~~~~~~~~~~~~~~~~~~~~~~~~~~~~~~~~~~~~~~~~~~~~~~~^^^^^^^^^^^^^
  File "/home/k4r4b0/Desktop/Projects/Python/Omnidesk/backend/app/api/auth.py", line 18, in login
    user = db.session.scalar(sa.select(User).where(User.username == data['username']))
  File "/home/k4r4b0/Desktop/Projects/Python/Omnidesk/backend/venv/lib/python3.13/site-packages/sqlalchemy/orm/scoping.py", line 1840, in scalar
    return self._proxied.scalar(
           ~~~~~~~~~~~~~~~~~~~~^
        statement,
        ^^^^^^^^^^
    ...<3 lines>...
        **kw,
        ^^^^^
    )
    ^
  File "/home/k4r4b0/Desktop/Projects/Python/Omnidesk/backend/venv/lib/python3.13/site-packages/sqlalchemy/orm/session.py", line 2413, in scalar
    return self._execute_internal(
           ~~~~~~~~~~~~~~~~~~~~~~^
        statement,
        ^^^^^^^^^^
    ...<4 lines>...
        **kw,
        ^^^^^
    )
    ^
  File "/home/k4r4b0/Desktop/Projects/Python/Omnidesk/backend/venv/lib/python3.13/site-packages/sqlalchemy/orm/session.py", line 2251, in _execute_internal
    result: Result[Any] = compile_state_cls.orm_execute_statement(
                          ~~~~~~~~~~~~~~~~~~~~~~~~~~~~~~~~~~~~~~~^
        self,
        ^^^^^
    ...<4 lines>...
        conn,
        ^^^^^
    )
    ^
  File "/home/k4r4b0/Desktop/Projects/Python/Omnidesk/backend/venv/lib/python3.13/site-packages/sqlalchemy/orm/context.py", line 306, in orm_execute_statement
    result = conn.execute(
        statement, params or {}, execution_options=execution_options
    )
  File "/home/k4r4b0/Desktop/Projects/Python/Omnidesk/backend/venv/lib/python3.13/site-packages/sqlalchemy/engine/base.py", line 1419, in execute
    return meth(
        self,
        distilled_parameters,
        execution_options or NO_OPTIONS,
    )
  File "/home/k4r4b0/Desktop/Projects/Python/Omnidesk/backend/venv/lib/python3.13/site-packages/sqlalchemy/sql/elements.py", line 526, in _execute_on_connection
    return connection._execute_clauseelement(
           ~~~~~~~~~~~~~~~~~~~~~~~~~~~~~~~~~^
        self, distilled_params, execution_options
        ^^^^^^^^^^^^^^^^^^^^^^^^^^^^^^^^^^^^^^^^^
    )
    ^
  File "/home/k4r4b0/Desktop/Projects/Python/Omnidesk/backend/venv/lib/python3.13/site-packages/sqlalchemy/engine/base.py", line 1641, in _execute_clauseelement
    ret = self._execute_context(
        dialect,
    ...<8 lines>...
        cache_hit=cache_hit,
    )
  File "/home/k4r4b0/Desktop/Projects/Python/Omnidesk/backend/venv/lib/python3.13/site-packages/sqlalchemy/engine/base.py", line 1846, in _execute_context
    return self._exec_single_context(
           ~~~~~~~~~~~~~~~~~~~~~~~~~^
        dialect, context, statement, parameters
        ^^^^^^^^^^^^^^^^^^^^^^^^^^^^^^^^^^^^^^^
    )
    ^
  File "/home/k4r4b0/Desktop/Projects/Python/Omnidesk/backend/venv/lib/python3.13/site-packages/sqlalchemy/engine/base.py", line 1986, in _exec_single_context
    self._handle_dbapi_exception(
    ~~~~~~~~~~~~~~~~~~~~~~~~~~~~^
        e, str_statement, effective_parameters, cursor, context
        ^^^^^^^^^^^^^^^^^^^^^^^^^^^^^^^^^^^^^^^^^^^^^^^^^^^^^^^
    )
    ^
  File "/home/k4r4b0/Desktop/Projects/Python/Omnidesk/backend/venv/lib/python3.13/site-packages/sqlalchemy/engine/base.py", line 2355, in _handle_dbapi_exception
    raise sqlalchemy_exception.with_traceback(exc_info[2]) from e
  File "/home/k4r4b0/Desktop/Projects/Python/Omnidesk/backend/venv/lib/python3.13/site-packages/sqlalchemy/engine/base.py", line 1967, in _exec_single_context
    self.dialect.do_execute(
    ~~~~~~~~~~~~~~~~~~~~~~~^
        cursor, str_statement, effective_parameters, context
        ^^^^^^^^^^^^^^^^^^^^^^^^^^^^^^^^^^^^^^^^^^^^^^^^^^^^
    )
    ^
  File "/home/k4r4b0/Desktop/Projects/Python/Omnidesk/backend/venv/lib/python3.13/site-packages/sqlalchemy/engine/default.py", line 951, in do_execute
    cursor.execute(statement, parameters)
    ~~~~~~~~~~~~~~^^^^^^^^^^^^^^^^^^^^^^^
sqlalchemy.exc.OperationalError: (sqlite3.OperationalError) no such column: user.is_active
[SQL: SELECT user.id, user.username, user.email, user.password_hash, user.about_me, user.last_seen, user.is_admin, user.is_active, user.created_at, user.phone, user.department, user.job_title, user.timezone, user.email_notifications 
FROM user 
WHERE user.username = ?]
[parameters: ('txo',)]
(Background on this error at: https://sqlalche.me/e/20/e3q8)
2025-08-16 20:05:15,844 INFO: OMNIDESK startup [in /home/k4r4b0/Desktop/Projects/Python/Omnidesk/backend/app/__init__.py:111]
2025-08-16 20:06:02,438 INFO: OMNIDESK startup [in /home/k4r4b0/Desktop/Projects/Python/Omnidesk/backend/app/__init__.py:111]
2025-08-16 20:06:50,022 INFO: OMNIDESK startup [in /home/k4r4b0/Desktop/Projects/Python/Omnidesk/backend/app/__init__.py:111]
2025-08-16 20:07:23,228 INFO: OMNIDESK startup [in /home/k4r4b0/Desktop/Projects/Python/Omnidesk/backend/app/__init__.py:111]
2025-08-16 20:07:47,098 INFO: OMNIDESK startup [in /home/k4r4b0/Desktop/Projects/Python/Omnidesk/backend/app/__init__.py:111]
2025-08-16 20:08:24,928 INFO: OMNIDESK startup [in /home/k4r4b0/Desktop/Projects/Python/Omnidesk/backend/app/__init__.py:111]
2025-08-16 20:10:13,485 INFO: OMNIDESK startup [in /home/k4r4b0/Desktop/Projects/Python/Omnidesk/backend/app/__init__.py:111]
2025-08-18 05:11:10,777 INFO: OMNIDESK startup [in /home/k4r4b0/Desktop/Projects/Python/Omnidesk/backend/app/__init__.py:111]
2025-08-18 05:30:41,362 INFO: OMNIDESK startup [in /home/k4r4b0/Desktop/Projects/Python/Omnidesk/backend/app/__init__.py:111]
