2025-08-09 11:23:58,585 ERROR: Exception on /tickets [GET] [in /home/k4r4b0/Desktop/Projects/Python/Omnidesk/venv/lib/python3.13/site-packages/flask/app.py:875]
Traceback (most recent call last):
  File "/home/k4r4b0/Desktop/Projects/Python/Omnidesk/venv/lib/python3.13/site-packages/flask/app.py", line 1511, in wsgi_app
    response = self.full_dispatch_request()
  File "/home/k4r4b0/Desktop/Projects/Python/Omnidesk/venv/lib/python3.13/site-packages/flask/app.py", line 919, in full_dispatch_request
    rv = self.handle_user_exception(e)
  File "/home/k4r4b0/Desktop/Projects/Python/Omnidesk/venv/lib/python3.13/site-packages/flask/app.py", line 917, in full_dispatch_request
    rv = self.dispatch_request()
  File "/home/k4r4b0/Desktop/Projects/Python/Omnidesk/venv/lib/python3.13/site-packages/flask/app.py", line 902, in dispatch_request
    return self.ensure_sync(self.view_functions[rule.endpoint])(**view_args)  # type: ignore[no-any-return]
           ~~~~~~~~~~~~~~~~~~~~~~~~~~~~~~~~~~~~~~~~~~~~~~~~~~~~^^^^^^^^^^^^^
  File "/home/k4r4b0/Desktop/Projects/Python/Omnidesk/venv/lib/python3.13/site-packages/flask_login/utils.py", line 290, in decorated_view
    return current_app.ensure_sync(func)(*args, **kwargs)
           ~~~~~~~~~~~~~~~~~~~~~~~~~~~~~^^^^^^^^^^^^^^^^^
  File "/home/k4r4b0/Desktop/Projects/Python/Omnidesk/app/routes.py", line 104, in tickets
    return render_template('tickets.html', title='Tickets', tickets=all_tickets)
  File "/home/k4r4b0/Desktop/Projects/Python/Omnidesk/venv/lib/python3.13/site-packages/flask/templating.py", line 150, in render_template
    return _render(app, template, context)
  File "/home/k4r4b0/Desktop/Projects/Python/Omnidesk/venv/lib/python3.13/site-packages/flask/templating.py", line 131, in _render
    rv = template.render(context)
  File "/home/k4r4b0/Desktop/Projects/Python/Omnidesk/venv/lib/python3.13/site-packages/jinja2/environment.py", line 1295, in render
    self.environment.handle_exception()
    ~~~~~~~~~~~~~~~~~~~~~~~~~~~~~~~~~^^
  File "/home/k4r4b0/Desktop/Projects/Python/Omnidesk/venv/lib/python3.13/site-packages/jinja2/environment.py", line 942, in handle_exception
    raise rewrite_traceback_stack(source=source)
  File "/home/k4r4b0/Desktop/Projects/Python/Omnidesk/app/templates/tickets.html", line 1, in top-level template code
    {% extends "base.html" %}
  File "/home/k4r4b0/Desktop/Projects/Python/Omnidesk/app/templates/base.html", line 88, in top-level template code
    {% block content %}{% endblock %}
    ^^^^^^^^^^^^^^^^^^^
  File "/home/k4r4b0/Desktop/Projects/Python/Omnidesk/app/templates/tickets.html", line 24, in block 'content'
    <td>{{ ticket.created_by.username }}</td>
    ^^^^^^^^^^^^^
  File "/home/k4r4b0/Desktop/Projects/Python/Omnidesk/venv/lib/python3.13/site-packages/jinja2/environment.py", line 490, in getattr
    return getattr(obj, attribute)
jinja2.exceptions.UndefinedError: 'app.models.Ticket object' has no attribute 'created_by'
