2025-08-09 07:15:48,071 ERROR: Exception on /register [POST] [in /home/k4r4b0/Desktop/Projects/Python/Omnidesk/venv/lib/python3.13/site-packages/flask/app.py:875]
Traceback (most recent call last):
  File "/home/k4r4b0/Desktop/Projects/Python/Omnidesk/venv/lib/python3.13/site-packages/sqlalchemy/engine/base.py", line 1961, in _exec_single_context
    self.dialect.do_execute(
    ~~~~~~~~~~~~~~~~~~~~~~~^
        cursor, str_statement, effective_parameters, context
        ^^^^^^^^^^^^^^^^^^^^^^^^^^^^^^^^^^^^^^^^^^^^^^^^^^^^
    )
    ^
  File "/home/k4r4b0/Desktop/Projects/Python/Omnidesk/venv/lib/python3.13/site-packages/sqlalchemy/engine/default.py", line 944, in do_execute
    cursor.execute(statement, parameters)
    ~~~~~~~~~~~~~~^^^^^^^^^^^^^^^^^^^^^^^
sqlite3.OperationalError: no such column: user.last_seen

The above exception was the direct cause of the following exception:

Traceback (most recent call last):
  File "/home/k4r4b0/Desktop/Projects/Python/Omnidesk/venv/lib/python3.13/site-packages/flask/app.py", line 1511, in wsgi_app
    response = self.full_dispatch_request()
  File "/home/k4r4b0/Desktop/Projects/Python/Omnidesk/venv/lib/python3.13/site-packages/flask/app.py", line 919, in full_dispatch_request
    rv = self.handle_user_exception(e)
  File "/home/k4r4b0/Desktop/Projects/Python/Omnidesk/venv/lib/python3.13/site-packages/flask/app.py", line 917, in full_dispatch_request
    rv = self.dispatch_request()
  File "/home/k4r4b0/Desktop/Projects/Python/Omnidesk/venv/lib/python3.13/site-packages/flask/app.py", line 902, in dispatch_request
    return self.ensure_sync(self.view_functions[rule.endpoint])(**view_args)  # type: ignore[no-any-return]
           ~~~~~~~~~~~~~~~~~~~~~~~~~~~~~~~~~~~~~~~~~~~~~~~~~~~~^^^^^^^^^^^^^
  File "/home/k4r4b0/Desktop/Projects/Python/Omnidesk/app/routes.py", line 125, in register
    if form.validate_on_submit():
       ~~~~~~~~~~~~~~~~~~~~~~~^^
  File "/home/k4r4b0/Desktop/Projects/Python/Omnidesk/venv/lib/python3.13/site-packages/flask_wtf/form.py", line 86, in validate_on_submit
    return self.is_submitted() and self.validate(extra_validators=extra_validators)
                                   ~~~~~~~~~~~~~^^^^^^^^^^^^^^^^^^^^^^^^^^^^^^^^^^^
  File "/home/k4r4b0/Desktop/Projects/Python/Omnidesk/venv/lib/python3.13/site-packages/wtforms/form.py", line 330, in validate
    return super().validate(extra)
           ~~~~~~~~~~~~~~~~^^^^^^^
  File "/home/k4r4b0/Desktop/Projects/Python/Omnidesk/venv/lib/python3.13/site-packages/wtforms/form.py", line 147, in validate
    if not field.validate(self, extra):
           ~~~~~~~~~~~~~~^^^^^^^^^^^^^
  File "/home/k4r4b0/Desktop/Projects/Python/Omnidesk/venv/lib/python3.13/site-packages/wtforms/fields/core.py", line 234, in validate
    stop_validation = self._run_validation_chain(form, chain)
  File "/home/k4r4b0/Desktop/Projects/Python/Omnidesk/venv/lib/python3.13/site-packages/wtforms/fields/core.py", line 254, in _run_validation_chain
    validator(form, self)
    ~~~~~~~~~^^^^^^^^^^^^
  File "/home/k4r4b0/Desktop/Projects/Python/Omnidesk/app/forms.py", line 27, in validate_username
    user = db.session.scalar(sa.select(User).where(
        User.username == username.data))
  File "/home/k4r4b0/Desktop/Projects/Python/Omnidesk/venv/lib/python3.13/site-packages/sqlalchemy/orm/scoping.py", line 1840, in scalar
    return self._proxied.scalar(
           ~~~~~~~~~~~~~~~~~~~~^
        statement,
        ^^^^^^^^^^
    ...<3 lines>...
        **kw,
        ^^^^^
    )
    ^
  File "/home/k4r4b0/Desktop/Projects/Python/Omnidesk/venv/lib/python3.13/site-packages/sqlalchemy/orm/session.py", line 2413, in scalar
    return self._execute_internal(
           ~~~~~~~~~~~~~~~~~~~~~~^
        statement,
        ^^^^^^^^^^
    ...<4 lines>...
        **kw,
        ^^^^^
    )
    ^
  File "/home/k4r4b0/Desktop/Projects/Python/Omnidesk/venv/lib/python3.13/site-packages/sqlalchemy/orm/session.py", line 2251, in _execute_internal
    result: Result[Any] = compile_state_cls.orm_execute_statement(
                          ~~~~~~~~~~~~~~~~~~~~~~~~~~~~~~~~~~~~~~~^
        self,
        ^^^^^
    ...<4 lines>...
        conn,
        ^^^^^
    )
    ^
  File "/home/k4r4b0/Desktop/Projects/Python/Omnidesk/venv/lib/python3.13/site-packages/sqlalchemy/orm/context.py", line 306, in orm_execute_statement
    result = conn.execute(
        statement, params or {}, execution_options=execution_options
    )
  File "/home/k4r4b0/Desktop/Projects/Python/Omnidesk/venv/lib/python3.13/site-packages/sqlalchemy/engine/base.py", line 1413, in execute
    return meth(
        self,
        distilled_parameters,
        execution_options or NO_OPTIONS,
    )
  File "/home/k4r4b0/Desktop/Projects/Python/Omnidesk/venv/lib/python3.13/site-packages/sqlalchemy/sql/elements.py", line 526, in _execute_on_connection
    return connection._execute_clauseelement(
           ~~~~~~~~~~~~~~~~~~~~~~~~~~~~~~~~~^
        self, distilled_params, execution_options
        ^^^^^^^^^^^^^^^^^^^^^^^^^^^^^^^^^^^^^^^^^
    )
    ^
  File "/home/k4r4b0/Desktop/Projects/Python/Omnidesk/venv/lib/python3.13/site-packages/sqlalchemy/engine/base.py", line 1635, in _execute_clauseelement
    ret = self._execute_context(
        dialect,
    ...<8 lines>...
        cache_hit=cache_hit,
    )
  File "/home/k4r4b0/Desktop/Projects/Python/Omnidesk/venv/lib/python3.13/site-packages/sqlalchemy/engine/base.py", line 1840, in _execute_context
    return self._exec_single_context(
           ~~~~~~~~~~~~~~~~~~~~~~~~~^
        dialect, context, statement, parameters
        ^^^^^^^^^^^^^^^^^^^^^^^^^^^^^^^^^^^^^^^
    )
    ^
  File "/home/k4r4b0/Desktop/Projects/Python/Omnidesk/venv/lib/python3.13/site-packages/sqlalchemy/engine/base.py", line 1980, in _exec_single_context
    self._handle_dbapi_exception(
    ~~~~~~~~~~~~~~~~~~~~~~~~~~~~^
        e, str_statement, effective_parameters, cursor, context
        ^^^^^^^^^^^^^^^^^^^^^^^^^^^^^^^^^^^^^^^^^^^^^^^^^^^^^^^
    )
    ^
  File "/home/k4r4b0/Desktop/Projects/Python/Omnidesk/venv/lib/python3.13/site-packages/sqlalchemy/engine/base.py", line 2349, in _handle_dbapi_exception
    raise sqlalchemy_exception.with_traceback(exc_info[2]) from e
  File "/home/k4r4b0/Desktop/Projects/Python/Omnidesk/venv/lib/python3.13/site-packages/sqlalchemy/engine/base.py", line 1961, in _exec_single_context
    self.dialect.do_execute(
    ~~~~~~~~~~~~~~~~~~~~~~~^
        cursor, str_statement, effective_parameters, context
        ^^^^^^^^^^^^^^^^^^^^^^^^^^^^^^^^^^^^^^^^^^^^^^^^^^^^
    )
    ^
  File "/home/k4r4b0/Desktop/Projects/Python/Omnidesk/venv/lib/python3.13/site-packages/sqlalchemy/engine/default.py", line 944, in do_execute
    cursor.execute(statement, parameters)
    ~~~~~~~~~~~~~~^^^^^^^^^^^^^^^^^^^^^^^
sqlalchemy.exc.OperationalError: (sqlite3.OperationalError) no such column: user.last_seen
[SQL: SELECT user.id, user.username, user.email, user.password_hash, user.about_me, user.last_seen 
FROM user 
WHERE user.username = ?]
[parameters: ('K4R4B0 ',)]
(Background on this error at: https://sqlalche.me/e/20/e3q8)
2025-08-09 07:24:59,714 INFO: OMNIDESK startup [in /home/k4r4b0/Desktop/Projects/Python/Omnidesk/app/__init__.py:44]
2025-08-09 07:25:04,484 INFO: OMNIDESK startup [in /home/k4r4b0/Desktop/Projects/Python/Omnidesk/app/__init__.py:44]
2025-08-09 07:25:13,540 INFO: OMNIDESK startup [in /home/k4r4b0/Desktop/Projects/Python/Omnidesk/app/__init__.py:44]
